const { validationResult } = require("express-validator");

const HttpError = require("../models/http-error");
const User = require("../models/user");

const getUsers = async (req, res, next) => {
  let users;
  try {
    users = await User.find({}, "-password");
  } catch (err) {
    const error = new HttpError("failed", 500);
    return next(error);
  }
  res.json({ users: users.map((user) => user.toObject({ getters: true })) });
};

const signup = async (req, res, next) => {
  const errors = validationResult(req);

  if (!errors.isEmpty()) {
    return next(new HttpError("Invalid input passed", 422));
  }

  const { name, email, password } = req.body;

  let existingUser;
  try {
    existingUser = await User.findOne({ email: email });
  } catch (err) {
    const error = new HttpError(
      "Signing up failed, please try again later",
      500
    );
    return next(error);
  }

  if (existingUser) {
    const error = new HttpError("User exists already", 422);
    return next(error);
  }

  const createdUser = new User({
    name,
    email,
    image: req.file.path,
    password,
    places: [],
  });

  try {
    await createdUser.save();
  } catch (err) {
    const error = new HttpError("Signup failed", 500);
    return next(error);
  }

  res.status(201).json({ user: createdUser.toObject({ getters: true }) });
};

const login = async (req, res, next) => {
  const { email, password } = req.body;

  let existingUser;

  try {
    existingUser = await User.findOne({ email: email });
  } catch (err) {
    const error = new HttpError("logging failed, please try again later", 500);
    return next(error);
  }

  if (!existingUser || existingUser.password !== password) {
    const error = new HttpError("Invalid Credentials", 401);
    return next(error);
  }

  res.json({
    message: "Logged in!",
    user: existingUser.toObject({ getters: true }),
  });
};

exports.getUsers = getUsers;
exports.signup = signup;
exports.login = login;
